{
 "cells": [
  {
   "cell_type": "code",
   "execution_count": 1,
   "metadata": {},
   "outputs": [
    {
     "name": "stderr",
     "output_type": "stream",
     "text": [
      "2024-12-30 22:32:29.962062: E external/local_xla/xla/stream_executor/cuda/cuda_fft.cc:477] Unable to register cuFFT factory: Attempting to register factory for plugin cuFFT when one has already been registered\n",
      "WARNING: All log messages before absl::InitializeLog() is called are written to STDERR\n",
      "E0000 00:00:1735565549.988125 1704750 cuda_dnn.cc:8310] Unable to register cuDNN factory: Attempting to register factory for plugin cuDNN when one has already been registered\n",
      "E0000 00:00:1735565549.996198 1704750 cuda_blas.cc:1418] Unable to register cuBLAS factory: Attempting to register factory for plugin cuBLAS when one has already been registered\n",
      "2024-12-30 22:32:30.022379: I tensorflow/core/platform/cpu_feature_guard.cc:210] This TensorFlow binary is optimized to use available CPU instructions in performance-critical operations.\n",
      "To enable the following instructions: AVX2 FMA, in other operations, rebuild TensorFlow with the appropriate compiler flags.\n"
     ]
    }
   ],
   "source": [
    "import tensorflow as tf\n",
    "from tensorflow import keras\n",
    "from tensorflow.keras import layers\n",
    "from tensorflow.keras.losses import SparseCategoricalCrossentropy\n",
    "from tensorflow.keras.optimizers import Adam\n",
    "\n",
    "(x_train, y_train), (x_test, y_test) = keras.datasets.cifar10.load_data()"
   ]
  },
  {
   "cell_type": "code",
   "execution_count": 2,
   "metadata": {},
   "outputs": [],
   "source": [
    "n_class=10\n",
    "img_siz=(32, 32, 3)\n",
    "\n",
    "patch_size=4\n",
    "p2=(img_siz[0]//patch_size)**2\n",
    "d_model=64\n",
    "h=8\n",
    "N=6"
   ]
  },
  {
   "cell_type": "code",
   "execution_count": 3,
   "metadata": {},
   "outputs": [],
   "source": [
    "class Patches(layers.Layer):\n",
    "    def __init__(self, patch_size):\n",
    "        super(Patches, self).__init__()\n",
    "        self.p_siz=patch_size\n",
    "        \n",
    "    def call(self, img):\n",
    "        batch_size=tf.shape(img)[0]\n",
    "        patches=tf.image.extract_patches(images=img,sizes=[1,self.p_siz,self.p_siz,1],strides=[1,self.p_siz,self.p_siz,1],rates=[1,1,1,1],padding='VALID')\n",
    "        patch_dims=patches.shape[-1]\n",
    "        patches=tf.reshape(patches, [batch_size,-1,patch_dims])\n",
    "        return patches\n",
    "    \n",
    "class PatchEncoder(layers.Layer):\n",
    "    def __init__(self, p2, d_model):\n",
    "        super(PatchEncoder, self).__init__()\n",
    "        self.p2=p2\n",
    "        self.projection=layers.Dense(units=d_model)\n",
    "        self.position_embedding=layers.Embedding(input_dim=p2, output_dim=d_model)\n",
    "        \n",
    "    def call(self, patch):\n",
    "        positions=tf.range(start=0, limit=self.p2, delta=1)\n",
    "        encoded=self.projection(patch)+self.position_embedding(positions)\n",
    "        return encoded"
   ]
  },
  {
   "cell_type": "code",
   "execution_count": 4,
   "metadata": {},
   "outputs": [],
   "source": [
    "def create_vit_classifier():\n",
    "    input=layers.Input(shape=(img_siz))\n",
    "    nor=layers.Normalization()(input)\n",
    "    \n",
    "    patches=Patches(patch_size)(nor)\n",
    "    x=PatchEncoder(p2, d_model)(patches)\n",
    "    \n",
    "    for _ in range(N):\n",
    "        x1=layers.LayerNormalization(epsilon=1e-6)(x)\n",
    "        x2=layers.MultiHeadAttention(num_heads=h, key_dim=d_model//h, dropout=0.1)(x1, x1)\n",
    "        x3=layers.Add()([x2, x])\n",
    "        x4=layers.LayerNormalization(epsilon=1e-6)(x3)\n",
    "        x5=layers.Dense(d_model*2, activation=tf.nn.gelu)(x4)\n",
    "        x6=layers.Dropout(0.1)(x5)\n",
    "        x7=layers.Dense(d_model, activation=tf.nn.gelu)(x6)\n",
    "        x8=layers.Dropout(0.1)(x7)\n",
    "        x=layers.Add()([x8, x3])\n",
    "        \n",
    "        x=layers.LayerNormalization(epsilon=1e-6)(x)\n",
    "        x=layers.Flatten()(x)\n",
    "        x=layers.Dropout(0.5)(x)\n",
    "        x=layers.Dense(2048, activation=tf.nn.gelu)(x)\n",
    "        x=layers.Dropout(0.5)(x)\n",
    "        x=layers.Dense(1024, activation=tf.nn.gelu)(x)\n",
    "        x=layers.Dropout(0.5)(x)\n",
    "        output=layers.Dense(n_class, activation='softmax')(x)\n",
    "        \n",
    "        model=keras.Model(inputs=input, outputs=output)\n",
    "        return model"
   ]
  },
  {
   "cell_type": "code",
   "execution_count": 6,
   "metadata": {},
   "outputs": [
    {
     "name": "stdout",
     "output_type": "stream",
     "text": [
      "Epoch 1/100\n"
     ]
    },
    {
     "name": "stderr",
     "output_type": "stream",
     "text": [
      "E0000 00:00:1735565607.925071 1704947 cuda_dnn.cc:522] Loaded runtime CuDNN library: 9.1.0 but source was compiled with: 9.3.0.  CuDNN library needs to have matching major version and equal or higher minor version. If using a binary install, upgrade your CuDNN library.  If building from sources, make sure the library loaded at runtime is compatible with the version specified during compile configuration.\n",
      "E0000 00:00:1735565608.440516 1704947 cuda_dnn.cc:522] Loaded runtime CuDNN library: 9.1.0 but source was compiled with: 9.3.0.  CuDNN library needs to have matching major version and equal or higher minor version. If using a binary install, upgrade your CuDNN library.  If building from sources, make sure the library loaded at runtime is compatible with the version specified during compile configuration.\n",
      "2024-12-30 22:33:28.461082: W tensorflow/core/framework/op_kernel.cc:1841] OP_REQUIRES failed at xla_ops.cc:577 : FAILED_PRECONDITION: DNN library initialization failed. Look at the errors above for more details.\n",
      "2024-12-30 22:33:28.461131: I tensorflow/core/framework/local_rendezvous.cc:405] Local rendezvous is aborting with status: FAILED_PRECONDITION: DNN library initialization failed. Look at the errors above for more details.\n",
      "\t [[{{node StatefulPartitionedCall}}]]\n"
     ]
    },
    {
     "ename": "FailedPreconditionError",
     "evalue": "Graph execution error:\n\nDetected at node StatefulPartitionedCall defined at (most recent call last):\n  File \"<frozen runpy>\", line 198, in _run_module_as_main\n\n  File \"<frozen runpy>\", line 88, in _run_code\n\n  File \"/home/bj/transformer/.wv/lib/python3.11/site-packages/ipykernel_launcher.py\", line 18, in <module>\n\n  File \"/home/bj/transformer/.wv/lib/python3.11/site-packages/traitlets/config/application.py\", line 1075, in launch_instance\n\n  File \"/home/bj/transformer/.wv/lib/python3.11/site-packages/ipykernel/kernelapp.py\", line 739, in start\n\n  File \"/home/bj/transformer/.wv/lib/python3.11/site-packages/tornado/platform/asyncio.py\", line 205, in start\n\n  File \"/usr/lib/python3.11/asyncio/base_events.py\", line 604, in run_forever\n\n  File \"/usr/lib/python3.11/asyncio/base_events.py\", line 1909, in _run_once\n\n  File \"/usr/lib/python3.11/asyncio/events.py\", line 80, in _run\n\n  File \"/home/bj/transformer/.wv/lib/python3.11/site-packages/ipykernel/kernelbase.py\", line 545, in dispatch_queue\n\n  File \"/home/bj/transformer/.wv/lib/python3.11/site-packages/ipykernel/kernelbase.py\", line 534, in process_one\n\n  File \"/home/bj/transformer/.wv/lib/python3.11/site-packages/ipykernel/kernelbase.py\", line 437, in dispatch_shell\n\n  File \"/home/bj/transformer/.wv/lib/python3.11/site-packages/ipykernel/ipkernel.py\", line 362, in execute_request\n\n  File \"/home/bj/transformer/.wv/lib/python3.11/site-packages/ipykernel/kernelbase.py\", line 778, in execute_request\n\n  File \"/home/bj/transformer/.wv/lib/python3.11/site-packages/ipykernel/ipkernel.py\", line 449, in do_execute\n\n  File \"/home/bj/transformer/.wv/lib/python3.11/site-packages/ipykernel/zmqshell.py\", line 549, in run_cell\n\n  File \"/home/bj/transformer/.wv/lib/python3.11/site-packages/IPython/core/interactiveshell.py\", line 3075, in run_cell\n\n  File \"/home/bj/transformer/.wv/lib/python3.11/site-packages/IPython/core/interactiveshell.py\", line 3130, in _run_cell\n\n  File \"/home/bj/transformer/.wv/lib/python3.11/site-packages/IPython/core/async_helpers.py\", line 128, in _pseudo_sync_runner\n\n  File \"/home/bj/transformer/.wv/lib/python3.11/site-packages/IPython/core/interactiveshell.py\", line 3334, in run_cell_async\n\n  File \"/home/bj/transformer/.wv/lib/python3.11/site-packages/IPython/core/interactiveshell.py\", line 3517, in run_ast_nodes\n\n  File \"/home/bj/transformer/.wv/lib/python3.11/site-packages/IPython/core/interactiveshell.py\", line 3577, in run_code\n\n  File \"/tmp/ipykernel_1704750/511225444.py\", line 5, in <module>\n\n  File \"/home/bj/transformer/.wv/lib/python3.11/site-packages/keras/src/utils/traceback_utils.py\", line 117, in error_handler\n\n  File \"/home/bj/transformer/.wv/lib/python3.11/site-packages/keras/src/backend/tensorflow/trainer.py\", line 368, in fit\n\n  File \"/home/bj/transformer/.wv/lib/python3.11/site-packages/keras/src/backend/tensorflow/trainer.py\", line 216, in function\n\n  File \"/home/bj/transformer/.wv/lib/python3.11/site-packages/keras/src/backend/tensorflow/trainer.py\", line 129, in multi_step_on_iterator\n\nDNN library initialization failed. Look at the errors above for more details.\n\t [[{{node StatefulPartitionedCall}}]] [Op:__inference_multi_step_on_iterator_12970]",
     "output_type": "error",
     "traceback": [
      "\u001b[0;31m---------------------------------------------------------------------------\u001b[0m",
      "\u001b[0;31mFailedPreconditionError\u001b[0m                   Traceback (most recent call last)",
      "Cell \u001b[0;32mIn[6], line 5\u001b[0m\n\u001b[1;32m      2\u001b[0m model\u001b[38;5;241m.\u001b[39mlayers[\u001b[38;5;241m1\u001b[39m]\u001b[38;5;241m.\u001b[39madapt(x_train)\n\u001b[1;32m      4\u001b[0m model\u001b[38;5;241m.\u001b[39mcompile(optimizer\u001b[38;5;241m=\u001b[39mAdam(), loss\u001b[38;5;241m=\u001b[39mSparseCategoricalCrossentropy(from_logits\u001b[38;5;241m=\u001b[39m\u001b[38;5;28;01mFalse\u001b[39;00m), metrics\u001b[38;5;241m=\u001b[39m[\u001b[38;5;124m'\u001b[39m\u001b[38;5;124maccuracy\u001b[39m\u001b[38;5;124m'\u001b[39m])\n\u001b[0;32m----> 5\u001b[0m hist\u001b[38;5;241m=\u001b[39m\u001b[43mmodel\u001b[49m\u001b[38;5;241;43m.\u001b[39;49m\u001b[43mfit\u001b[49m\u001b[43m(\u001b[49m\u001b[43mx_train\u001b[49m\u001b[43m,\u001b[49m\u001b[43m \u001b[49m\u001b[43my_train\u001b[49m\u001b[43m,\u001b[49m\u001b[43m \u001b[49m\u001b[43mbatch_size\u001b[49m\u001b[38;5;241;43m=\u001b[39;49m\u001b[38;5;241;43m128\u001b[39;49m\u001b[43m,\u001b[49m\u001b[43m \u001b[49m\u001b[43mepochs\u001b[49m\u001b[38;5;241;43m=\u001b[39;49m\u001b[38;5;241;43m100\u001b[39;49m\u001b[43m,\u001b[49m\u001b[43m \u001b[49m\u001b[43mvalidation_data\u001b[49m\u001b[38;5;241;43m=\u001b[39;49m\u001b[43m(\u001b[49m\u001b[43mx_test\u001b[49m\u001b[43m,\u001b[49m\u001b[43m \u001b[49m\u001b[43my_test\u001b[49m\u001b[43m)\u001b[49m\u001b[43m,\u001b[49m\u001b[43m \u001b[49m\u001b[43mverbose\u001b[49m\u001b[38;5;241;43m=\u001b[39;49m\u001b[38;5;241;43m1\u001b[39;49m\u001b[43m)\u001b[49m\n\u001b[1;32m      7\u001b[0m res\u001b[38;5;241m=\u001b[39mmodel\u001b[38;5;241m.\u001b[39mevaluate(x_test, y_test, verbose\u001b[38;5;241m=\u001b[39m\u001b[38;5;241m0\u001b[39m)\n\u001b[1;32m      8\u001b[0m \u001b[38;5;28mprint\u001b[39m(\u001b[38;5;124m'\u001b[39m\u001b[38;5;124maccuracy=\u001b[39m\u001b[38;5;124m'\u001b[39m, res[\u001b[38;5;241m1\u001b[39m]\u001b[38;5;241m*\u001b[39m\u001b[38;5;241m100\u001b[39m)\n",
      "File \u001b[0;32m~/transformer/.wv/lib/python3.11/site-packages/keras/src/utils/traceback_utils.py:122\u001b[0m, in \u001b[0;36mfilter_traceback.<locals>.error_handler\u001b[0;34m(*args, **kwargs)\u001b[0m\n\u001b[1;32m    119\u001b[0m     filtered_tb \u001b[38;5;241m=\u001b[39m _process_traceback_frames(e\u001b[38;5;241m.\u001b[39m__traceback__)\n\u001b[1;32m    120\u001b[0m     \u001b[38;5;66;03m# To get the full stack trace, call:\u001b[39;00m\n\u001b[1;32m    121\u001b[0m     \u001b[38;5;66;03m# `keras.config.disable_traceback_filtering()`\u001b[39;00m\n\u001b[0;32m--> 122\u001b[0m     \u001b[38;5;28;01mraise\u001b[39;00m e\u001b[38;5;241m.\u001b[39mwith_traceback(filtered_tb) \u001b[38;5;28;01mfrom\u001b[39;00m \u001b[38;5;28;01mNone\u001b[39;00m\n\u001b[1;32m    123\u001b[0m \u001b[38;5;28;01mfinally\u001b[39;00m:\n\u001b[1;32m    124\u001b[0m     \u001b[38;5;28;01mdel\u001b[39;00m filtered_tb\n",
      "File \u001b[0;32m~/transformer/.wv/lib/python3.11/site-packages/tensorflow/python/eager/execute.py:53\u001b[0m, in \u001b[0;36mquick_execute\u001b[0;34m(op_name, num_outputs, inputs, attrs, ctx, name)\u001b[0m\n\u001b[1;32m     51\u001b[0m \u001b[38;5;28;01mtry\u001b[39;00m:\n\u001b[1;32m     52\u001b[0m   ctx\u001b[38;5;241m.\u001b[39mensure_initialized()\n\u001b[0;32m---> 53\u001b[0m   tensors \u001b[38;5;241m=\u001b[39m pywrap_tfe\u001b[38;5;241m.\u001b[39mTFE_Py_Execute(ctx\u001b[38;5;241m.\u001b[39m_handle, device_name, op_name,\n\u001b[1;32m     54\u001b[0m                                       inputs, attrs, num_outputs)\n\u001b[1;32m     55\u001b[0m \u001b[38;5;28;01mexcept\u001b[39;00m core\u001b[38;5;241m.\u001b[39m_NotOkStatusException \u001b[38;5;28;01mas\u001b[39;00m e:\n\u001b[1;32m     56\u001b[0m   \u001b[38;5;28;01mif\u001b[39;00m name \u001b[38;5;129;01mis\u001b[39;00m \u001b[38;5;129;01mnot\u001b[39;00m \u001b[38;5;28;01mNone\u001b[39;00m:\n",
      "\u001b[0;31mFailedPreconditionError\u001b[0m: Graph execution error:\n\nDetected at node StatefulPartitionedCall defined at (most recent call last):\n  File \"<frozen runpy>\", line 198, in _run_module_as_main\n\n  File \"<frozen runpy>\", line 88, in _run_code\n\n  File \"/home/bj/transformer/.wv/lib/python3.11/site-packages/ipykernel_launcher.py\", line 18, in <module>\n\n  File \"/home/bj/transformer/.wv/lib/python3.11/site-packages/traitlets/config/application.py\", line 1075, in launch_instance\n\n  File \"/home/bj/transformer/.wv/lib/python3.11/site-packages/ipykernel/kernelapp.py\", line 739, in start\n\n  File \"/home/bj/transformer/.wv/lib/python3.11/site-packages/tornado/platform/asyncio.py\", line 205, in start\n\n  File \"/usr/lib/python3.11/asyncio/base_events.py\", line 604, in run_forever\n\n  File \"/usr/lib/python3.11/asyncio/base_events.py\", line 1909, in _run_once\n\n  File \"/usr/lib/python3.11/asyncio/events.py\", line 80, in _run\n\n  File \"/home/bj/transformer/.wv/lib/python3.11/site-packages/ipykernel/kernelbase.py\", line 545, in dispatch_queue\n\n  File \"/home/bj/transformer/.wv/lib/python3.11/site-packages/ipykernel/kernelbase.py\", line 534, in process_one\n\n  File \"/home/bj/transformer/.wv/lib/python3.11/site-packages/ipykernel/kernelbase.py\", line 437, in dispatch_shell\n\n  File \"/home/bj/transformer/.wv/lib/python3.11/site-packages/ipykernel/ipkernel.py\", line 362, in execute_request\n\n  File \"/home/bj/transformer/.wv/lib/python3.11/site-packages/ipykernel/kernelbase.py\", line 778, in execute_request\n\n  File \"/home/bj/transformer/.wv/lib/python3.11/site-packages/ipykernel/ipkernel.py\", line 449, in do_execute\n\n  File \"/home/bj/transformer/.wv/lib/python3.11/site-packages/ipykernel/zmqshell.py\", line 549, in run_cell\n\n  File \"/home/bj/transformer/.wv/lib/python3.11/site-packages/IPython/core/interactiveshell.py\", line 3075, in run_cell\n\n  File \"/home/bj/transformer/.wv/lib/python3.11/site-packages/IPython/core/interactiveshell.py\", line 3130, in _run_cell\n\n  File \"/home/bj/transformer/.wv/lib/python3.11/site-packages/IPython/core/async_helpers.py\", line 128, in _pseudo_sync_runner\n\n  File \"/home/bj/transformer/.wv/lib/python3.11/site-packages/IPython/core/interactiveshell.py\", line 3334, in run_cell_async\n\n  File \"/home/bj/transformer/.wv/lib/python3.11/site-packages/IPython/core/interactiveshell.py\", line 3517, in run_ast_nodes\n\n  File \"/home/bj/transformer/.wv/lib/python3.11/site-packages/IPython/core/interactiveshell.py\", line 3577, in run_code\n\n  File \"/tmp/ipykernel_1704750/511225444.py\", line 5, in <module>\n\n  File \"/home/bj/transformer/.wv/lib/python3.11/site-packages/keras/src/utils/traceback_utils.py\", line 117, in error_handler\n\n  File \"/home/bj/transformer/.wv/lib/python3.11/site-packages/keras/src/backend/tensorflow/trainer.py\", line 368, in fit\n\n  File \"/home/bj/transformer/.wv/lib/python3.11/site-packages/keras/src/backend/tensorflow/trainer.py\", line 216, in function\n\n  File \"/home/bj/transformer/.wv/lib/python3.11/site-packages/keras/src/backend/tensorflow/trainer.py\", line 129, in multi_step_on_iterator\n\nDNN library initialization failed. Look at the errors above for more details.\n\t [[{{node StatefulPartitionedCall}}]] [Op:__inference_multi_step_on_iterator_12970]"
     ]
    }
   ],
   "source": [
    "model=create_vit_classifier()\n",
    "model.layers[1].adapt(x_train)\n",
    "\n",
    "model.compile(optimizer=Adam(), loss=SparseCategoricalCrossentropy(from_logits=False), metrics=['accuracy'])\n",
    "hist=model.fit(x_train, y_train, batch_size=128, epochs=100, validation_data=(x_test, y_test), verbose=1)\n",
    "\n",
    "res=model.evaluate(x_test, y_test, verbose=0)\n",
    "print('accuracy=', res[1]*100)"
   ]
  },
  {
   "cell_type": "code",
   "execution_count": null,
   "metadata": {},
   "outputs": [],
   "source": []
  }
 ],
 "metadata": {
  "kernelspec": {
   "display_name": ".wv",
   "language": "python",
   "name": "python3"
  },
  "language_info": {
   "codemirror_mode": {
    "name": "ipython",
    "version": 3
   },
   "file_extension": ".py",
   "mimetype": "text/x-python",
   "name": "python",
   "nbconvert_exporter": "python",
   "pygments_lexer": "ipython3",
   "version": "3.11.0"
  }
 },
 "nbformat": 4,
 "nbformat_minor": 2
}
